Workbook

Sheet Project Info
A1: GlimmoraTeam — Feature Delivery Tracker
A2: Standard program register · Phase 1 MVP
A4: Project name | B4: GlimmoraTeam Global Workforce Platform
A5: Document owner | B5: Product / Engineering
A6: Version | B6: 1.0
A7: Last updated | B7: 46170
A8: Reporting period | B8: Phase 1 (Apr – Aug 2026)
A9: Project manager | B9: [Name]
A10: Engineering manager | B10: [Name]
A11: Status cadence | B11: Weekly — update Assigned To, statuses, and % Complete
A13: Navigation
A14: Sheet | B14: Purpose
A15: Feature Register | B15: Master tracker — edit here
A16: Dashboard | B16: Executive summary (auto-calculated)
A17: Resource Plan | B17: Assignee workload view
A18: Definitions | B18: Column and status definitions

Sheet Feature Register
A1: Feature Register
A2: Single source of truth · Filter by Module, Assigned To, or Overall Status
A11: Feature ID | B11: Module | C11: Feature Name | D11: Description | E11: Priority | F11: Phase | G11: Overall Status | H11: Frontend Status | I11: Backend Status | J11: % Complete | K11: RAG | L11: Assigned To | M11: Accountable (EM) | N11: Planned Start | O11: Planned End | P11: Actual End | Q11: Last Updated | R11: Dependency ID | S11: Remarks
A12: FTR-001 | B12: Platform | C12: Application shell & routing | D12: Multi-portal Next.js App Router with role-based layouts | E12: P1 — Critical | F12: Phase 1 — MVP | G12: Completed | H12: Complete | I12: Complete | J12: =IF(G12="Completed",100,IF(G12="Deferred",0,IF(G12="Cancelled",0,IF(G12="Not Started",0,IF(G12="On Hold",IF(OR(H12="Complete",H12="N/A"),50,25),ROUND((IF(H12="Complete",100,IF(H12="In Progress",50,IF(H12="Blocked",25,0)))+IF(I12="Complete",100,IF(I12="In Progress",50,IF(I12="Blocked",25,IF(I12="N/A",100,0)))))/2,0)))))) | K12: =IF(G12="Completed","Green",IF(G12="Deferred","Grey",IF(G12="Cancelled","Grey",IF(G12="On Hold","Red",IF(J12>=80,"Green",IF(J12>=40,"Amber","Red")))))) | L12: Frontend Lead | M12: Engineering Manager | N12: 46082 | O12: 46142 | Q12: 46170 | R12: — | S12: Production-ready
A13: FTR-002 | B13: Platform | C13: Authentication (email / password) | D13: Login, registration, password reset, session management | E13: P1 — Critical | F13: Phase 1 — MVP | G13: Completed | H13: Complete | I13: Complete | J13: =IF(G13="Completed",100,IF(G13="Deferred",0,IF(G13="Cancelled",0,IF(G13="Not Started",0,IF(G13="On Hold",IF(OR(H13="Complete",H13="N/A"),50,25),ROUND((IF(H13="Complete",100,IF(H13="In Progress",50,IF(H13="Blocked",25,0)))+IF(I13="Complete",100,IF(I13="In Progress",50,IF(I13="Blocked",25,IF(I13="N/A",100,0)))))/2,0)))))) | K13: =IF(G13="Completed","Green",IF(G13="Deferred","Grey",IF(G13="Cancelled","Grey",IF(G13="On Hold","Red",IF(J13>=80,"Green",IF(J13>=40,"Amber","Red")))))) | L13: Backend Lead | M13: Engineering Manager | N13: 46082 | O13: 46127 | Q13: 46170 | R13: FTR-008 | S13: NextAuth v5 + Prisma
A14: FTR-003 | B14: Platform | C14: OAuth (Google & Microsoft) | D14: SSO sign-in for contributors and enterprise users | E14: P1 — Critical | F14: Phase 1 — MVP | G14: In Progress | H14: Complete | I14: In Progress | J14: =IF(G14="Completed",100,IF(G14="Deferred",0,IF(G14="Cancelled",0,IF(G14="Not Started",0,IF(G14="On Hold",IF(OR(H14="Complete",H14="N/A"),50,25),ROUND((IF(H14="Complete",100,IF(H14="In Progress",50,IF(H14="Blocked",25,0)))+IF(I14="Complete",100,IF(I14="In Progress",50,IF(I14="Blocked",25,IF(I14="N/A",100,0)))))/2,0)))))) | K14: =IF(G14="Completed","Green",IF(G14="Deferred","Grey",IF(G14="Cancelled","Grey",IF(G14="On Hold","Red",IF(J14>=80,"Green",IF(J14>=40,"Amber","Red")))))) | L14: Backend Lead | M14: Engineering Manager | N14: 46113 | O14: 46188 | Q14: 46170 | R14: FTR-002 | S14: Enterprise IdP routing partial
A15: FTR-004 | B15: Platform | C15: MFA / TOTP | D15: Multi-factor authentication setup and verification | E15: P2 — High | F15: Phase 1 — Hardening | G15: In Progress | H15: Complete | I15: In Progress | J15: =IF(G15="Completed",100,IF(G15="Deferred",0,IF(G15="Cancelled",0,IF(G15="Not Started",0,IF(G15="On Hold",IF(OR(H15="Complete",H15="N/A"),50,25),ROUND((IF(H15="Complete",100,IF(H15="In Progress",50,IF(H15="Blocked",25,0)))+IF(I15="Complete",100,IF(I15="In Progress",50,IF(I15="Blocked",25,IF(I15="N/A",100,0)))))/2,0)))))) | K15: =IF(G15="Completed","Green",IF(G15="Deferred","Grey",IF(G15="Cancelled","Grey",IF(G15="On Hold","Red",IF(J15>=80,"Green",IF(J15>=40,"Amber","Red")))))) | L15: Security Lead | M15: Engineering Manager | N15: 46143 | O15: 46203 | Q15: 46170 | R15: FTR-002 | S15: E2E coverage pending
A16: FTR-005 | B16: Platform | C16: OTP (email & phone) | D16: One-time password verification flows | E16: P2 — High | F16: Phase 1 — MVP | G16: Completed | H16: Complete | I16: Complete | J16: =IF(G16="Completed",100,IF(G16="Deferred",0,IF(G16="Cancelled",0,IF(G16="Not Started",0,IF(G16="On Hold",IF(OR(H16="Complete",H16="N/A"),50,25),ROUND((IF(H16="Complete",100,IF(H16="In Progress",50,IF(H16="Blocked",25,0)))+IF(I16="Complete",100,IF(I16="In Progress",50,IF(I16="Blocked",25,IF(I16="N/A",100,0)))))/2,0)))))) | K16: =IF(G16="Completed","Green",IF(G16="Deferred","Grey",IF(G16="Cancelled","Grey",IF(G16="On Hold","Red",IF(J16>=80,"Green",IF(J16>=40,"Amber","Red")))))) | L16: Backend Lead | M16: Engineering Manager | N16: 46113 | O16: 46143 | Q16: 46170 | R16: FTR-011 | S16: Live
A17: FTR-006 | B17: Platform | C17: Role-based route guards | D17: Middleware and hooks enforcing portal access | E17: P1 — Critical | F17: Phase 1 — MVP | G17: In Progress | H17: Complete | I17: In Progress | J17: =IF(G17="Completed",100,IF(G17="Deferred",0,IF(G17="Cancelled",0,IF(G17="Not Started",0,IF(G17="On Hold",IF(OR(H17="Complete",H17="N/A"),50,25),ROUND((IF(H17="Complete",100,IF(H17="In Progress",50,IF(H17="Blocked",25,0)))+IF(I17="Complete",100,IF(I17="In Progress",50,IF(I17="Blocked",25,IF(I17="N/A",100,0)))))/2,0)))))) | K17: =IF(G17="Completed","Green",IF(G17="Deferred","Grey",IF(G17="Cancelled","Grey",IF(G17="On Hold","Red",IF(J17>=80,"Green",IF(J17>=40,"Amber","Red")))))) | L17: Platform Lead | M17: Engineering Manager | N17: 46127 | O17: 46174 | Q17: 46170 | R17: FTR-002 | S17: Demo bypass flags in dev
A18: FTR-007 | B18: Platform | C18: API authorization (RBAC audit) | D18: requireRole on all API route handlers | E18: P1 — Critical | F18: Phase 1 — Hardening | G18: In Progress | H18: N/A | I18: In Progress | J18: =IF(G18="Completed",100,IF(G18="Deferred",0,IF(G18="Cancelled",0,IF(G18="Not Started",0,IF(G18="On Hold",IF(OR(H18="Complete",H18="N/A"),50,25),ROUND((IF(H18="Complete",100,IF(H18="In Progress",50,IF(H18="Blocked",25,0)))+IF(I18="Complete",100,IF(I18="In Progress",50,IF(I18="Blocked",25,IF(I18="N/A",100,0)))))/2,0)))))) | K18: =IF(G18="Completed","Green",IF(G18="Deferred","Grey",IF(G18="Cancelled","Grey",IF(G18="On Hold","Red",IF(J18>=80,"Green",IF(J18>=40,"Amber","Red")))))) | L18: Backend Lead | M18: Engineering Manager | N18: 46157 | O18: 46188 | Q18: 46170 | R18: FTR-006 | S18: 2 of 28 routes wired
A19: FTR-008 | B19: Platform | C19: Database schema (Prisma + Postgres) | D19: Core domain models and migrations | E19: P1 — Critical | F19: Phase 1 — MVP | G19: In Progress | H19: N/A | I19: In Progress | J19: =IF(G19="Completed",100,IF(G19="Deferred",0,IF(G19="Cancelled",0,IF(G19="Not Started",0,IF(G19="On Hold",IF(OR(H19="Complete",H19="N/A"),50,25),ROUND((IF(H19="Complete",100,IF(H19="In Progress",50,IF(H19="Blocked",25,0)))+IF(I19="Complete",100,IF(I19="In Progress",50,IF(I19="Blocked",25,IF(I19="N/A",100,0)))))/2,0)))))) | K19: =IF(G19="Completed","Green",IF(G19="Deferred","Grey",IF(G19="Cancelled","Grey",IF(G19="On Hold","Red",IF(J19>=80,"Green",IF(J19>=40,"Amber","Red")))))) | L19: Backend Lead | M19: Engineering Manager | N19: 46096 | O19: 46203 | Q19: 46170 | R19: — | S19: Schema exists; many domains mock-backed
A20: FTR-009 | B20: Platform | C20: Observability (Sentry / logging) | D20: Error tracking, structured logs, alerting | E20: P1 — Critical | F20: Phase 1 — Hardening | G20: Not Started | H20: N/A | I20: Not Started | J20: =IF(G20="Completed",100,IF(G20="Deferred",0,IF(G20="Cancelled",0,IF(G20="Not Started",0,IF(G20="On Hold",IF(OR(H20="Complete",H20="N/A"),50,25),ROUND((IF(H20="Complete",100,IF(H20="In Progress",50,IF(H20="Blocked",25,0)))+IF(I20="Complete",100,IF(I20="In Progress",50,IF(I20="Blocked",25,IF(I20="N/A",100,0)))))/2,0)))))) | K20: =IF(G20="Completed","Green",IF(G20="Deferred","Grey",IF(G20="Cancelled","Grey",IF(G20="On Hold","Red",IF(J20>=80,"Green",IF(J20>=40,"Amber","Red")))))) | L20: DevOps / SRE | M20: Engineering Manager | N20: 46174 | O20: 46218 | Q20: 46170 | R20: — | S20: Production blocker
A21: FTR-010 | B21: Platform | C21: Security headers & CSRF | D21: CSP, rate limiting, CSRF middleware | E21: P1 — Critical | F21: Phase 1 — Hardening | G21: Not Started | H21: N/A | I21: Not Started | J21: =IF(G21="Completed",100,IF(G21="Deferred",0,IF(G21="Cancelled",0,IF(G21="Not Started",0,IF(G21="On Hold",IF(OR(H21="Complete",H21="N/A"),50,25),ROUND((IF(H21="Complete",100,IF(H21="In Progress",50,IF(H21="Blocked",25,0)))+IF(I21="Complete",100,IF(I21="In Progress",50,IF(I21="Blocked",25,IF(I21="N/A",100,0)))))/2,0)))))) | K21: =IF(G21="Completed","Green",IF(G21="Deferred","Grey",IF(G21="Cancelled","Grey",IF(G21="On Hold","Red",IF(J21>=80,"Green",IF(J21>=40,"Amber","Red")))))) | L21: Security Lead | M21: Engineering Manager | N21: 46188 | O21: 46204 | Q21: 46170 | R21: FTR-007
A22: FTR-011 | B22: Platform | C22: Transactional email | D22: Nodemailer + React Email templates | E22: P2 — High | F22: Phase 1 — MVP | G22: In Progress | H22: Complete | I22: In Progress | J22: =IF(G22="Completed",100,IF(G22="Deferred",0,IF(G22="Cancelled",0,IF(G22="Not Started",0,IF(G22="On Hold",IF(OR(H22="Complete",H22="N/A"),50,25),ROUND((IF(H22="Complete",100,IF(H22="In Progress",50,IF(H22="Blocked",25,0)))+IF(I22="Complete",100,IF(I22="In Progress",50,IF(I22="Blocked",25,IF(I22="N/A",100,0)))))/2,0)))))) | K22: =IF(G22="Completed","Green",IF(G22="Deferred","Grey",IF(G22="Cancelled","Grey",IF(G22="On Hold","Red",IF(J22>=80,"Green",IF(J22>=40,"Amber","Red")))))) | L22: Backend Lead | M22: Engineering Manager | N22: 46113 | O22: 46174 | Q22: 46170 | R22: — | S22: Rate limit + RBAC audit pending
A23: FTR-012 | B23: Platform | C23: Razorpay — order creation | D23: Enterprise milestone payment order intent | E23: P1 — Critical | F23: Phase 1 — MVP | G23: Completed | H23: Complete | I23: Complete | J23: =IF(G23="Completed",100,IF(G23="Deferred",0,IF(G23="Cancelled",0,IF(G23="Not Started",0,IF(G23="On Hold",IF(OR(H23="Complete",H23="N/A"),50,25),ROUND((IF(H23="Complete",100,IF(H23="In Progress",50,IF(H23="Blocked",25,0)))+IF(I23="Complete",100,IF(I23="In Progress",50,IF(I23="Blocked",25,IF(I23="N/A",100,0)))))/2,0)))))) | K23: =IF(G23="Completed","Green",IF(G23="Deferred","Grey",IF(G23="Cancelled","Grey",IF(G23="On Hold","Red",IF(J23>=80,"Green",IF(J23>=40,"Amber","Red")))))) | L23: Backend Lead | M23: Engineering Manager | N23: 46113 | O23: 46157 | Q23: 46170 | R23: FTR-048 | S23: Gated by acceptance decision
A24: FTR-013 | B24: Platform | C24: Razorpay — webhooks | D24: HMAC signature verification, idempotent events | E24: P1 — Critical | F24: Phase 1 — MVP | G24: Completed | H24: N/A | I24: Complete | J24: =IF(G24="Completed",100,IF(G24="Deferred",0,IF(G24="Cancelled",0,IF(G24="Not Started",0,IF(G24="On Hold",IF(OR(H24="Complete",H24="N/A"),50,25),ROUND((IF(H24="Complete",100,IF(H24="In Progress",50,IF(H24="Blocked",25,0)))+IF(I24="Complete",100,IF(I24="In Progress",50,IF(I24="Blocked",25,IF(I24="N/A",100,0)))))/2,0)))))) | K24: =IF(G24="Completed","Green",IF(G24="Deferred","Grey",IF(G24="Cancelled","Grey",IF(G24="On Hold","Red",IF(J24>=80,"Green",IF(J24>=40,"Amber","Red")))))) | L24: Backend Lead | M24: Engineering Manager | N24: 46127 | O24: 46157 | Q24: 46170 | R24: FTR-012 | S24: Shipped
A25: FTR-014 | B25: Platform | C25: Razorpay — payouts | D25: Platform to contributor payout leg | E25: P2 — High | F25: Phase 1 — Hardening | G25: Not Started | H25: In Progress | I25: Not Started | J25: =IF(G25="Completed",100,IF(G25="Deferred",0,IF(G25="Cancelled",0,IF(G25="Not Started",0,IF(G25="On Hold",IF(OR(H25="Complete",H25="N/A"),50,25),ROUND((IF(H25="Complete",100,IF(H25="In Progress",50,IF(H25="Blocked",25,0)))+IF(I25="Complete",100,IF(I25="In Progress",50,IF(I25="Blocked",25,IF(I25="N/A",100,0)))))/2,0)))))) | K25: =IF(G25="Completed","Green",IF(G25="Deferred","Grey",IF(G25="Cancelled","Grey",IF(G25="On Hold","Red",IF(J25>=80,"Green",IF(J25>=40,"Amber","Red")))))) | L25: Backend Lead | M25: Engineering Manager | N25: 46204 | O25: 46233 | Q25: 46170 | R25: FTR-012 | S25: Conditional on payout go-live
A26: FTR-015 | B26: Platform | C26: Audit log | D26: Immutable audit trail for state changes | E26: P1 — Critical | F26: Phase 1 — MVP | G26: In Progress | H26: Complete | I26: In Progress | J26: =IF(G26="Completed",100,IF(G26="Deferred",0,IF(G26="Cancelled",0,IF(G26="Not Started",0,IF(G26="On Hold",IF(OR(H26="Complete",H26="N/A"),50,25),ROUND((IF(H26="Complete",100,IF(H26="In Progress",50,IF(H26="Blocked",25,0)))+IF(I26="Complete",100,IF(I26="In Progress",50,IF(I26="Blocked",25,IF(I26="N/A",100,0)))))/2,0)))))) | K26: =IF(G26="Completed","Green",IF(G26="Deferred","Grey",IF(G26="Cancelled","Grey",IF(G26="On Hold","Red",IF(J26>=80,"Green",IF(J26>=40,"Amber","Red")))))) | L26: Backend Lead | M26: Engineering Manager | N26: 46113 | O26: 46188 | Q26: 46170 | R26: FTR-008 | S26: Acceptance decisions persisted
A27: FTR-016 | B27: Platform | C27: Subscription & plan gating | D27: SaaS plan limits, usage, feature gates | E27: P2 — High | F27: Phase 1 — MVP | G27: In Progress | H27: Complete | I27: In Progress | J27: =IF(G27="Completed",100,IF(G27="Deferred",0,IF(G27="Cancelled",0,IF(G27="Not Started",0,IF(G27="On Hold",IF(OR(H27="Complete",H27="N/A"),50,25),ROUND((IF(H27="Complete",100,IF(H27="In Progress",50,IF(H27="Blocked",25,0)))+IF(I27="Complete",100,IF(I27="In Progress",50,IF(I27="Blocked",25,IF(I27="N/A",100,0)))))/2,0)))))) | K27: =IF(G27="Completed","Green",IF(G27="Deferred","Grey",IF(G27="Cancelled","Grey",IF(G27="On Hold","Red",IF(J27>=80,"Green",IF(J27>=40,"Amber","Red")))))) | L27: Full Stack Developer | M27: Engineering Manager | N27: 46143 | O27: 46170 | Q27: 46170 | R27: FTR-008 | S27: Sidebar plan chip shipped
A28: FTR-017 | B28: Platform | C28: Backend API handoff | D28: External backend team scaffold + contract | E28: P2 — High | F28: Phase 1 — MVP | G28: In Progress | H28: Complete | I28: In Progress | J28: =IF(G28="Completed",100,IF(G28="Deferred",0,IF(G28="Cancelled",0,IF(G28="Not Started",0,IF(G28="On Hold",IF(OR(H28="Complete",H28="N/A"),50,25),ROUND((IF(H28="Complete",100,IF(H28="In Progress",50,IF(H28="Blocked",25,0)))+IF(I28="Complete",100,IF(I28="In Progress",50,IF(I28="Blocked",25,IF(I28="N/A",100,0)))))/2,0)))))) | K28: =IF(G28="Completed","Green",IF(G28="Deferred","Grey",IF(G28="Cancelled","Grey",IF(G28="On Hold","Red",IF(J28>=80,"Green",IF(J28>=40,"Amber","Red")))))) | L28: Engineering Manager | M28: Engineering Manager | N28: 46143 | O28: 46170 | Q28: 46170 | R28: — | S28: Frontend owns Prisma
A29: FTR-020 | B29: Contributor | C29: Dashboard | D29: Contributor home — tasks, progress, alerts | E29: P1 — Critical | F29: Phase 1 — MVP | G29: In Progress | H29: Complete | I29: In Progress | J29: =IF(G29="Completed",100,IF(G29="Deferred",0,IF(G29="Cancelled",0,IF(G29="Not Started",0,IF(G29="On Hold",IF(OR(H29="Complete",H29="N/A"),50,25),ROUND((IF(H29="Complete",100,IF(H29="In Progress",50,IF(H29="Blocked",25,0)))+IF(I29="Complete",100,IF(I29="In Progress",50,IF(I29="Blocked",25,IF(I29="N/A",100,0)))))/2,0)))))) | K29: =IF(G29="Completed","Green",IF(G29="Deferred","Grey",IF(G29="Cancelled","Grey",IF(G29="On Hold","Red",IF(J29>=80,"Green",IF(J29>=40,"Amber","Red")))))) | L29: Frontend Lead | M29: Engineering Manager | N29: 46113 | O29: 46143 | Q29: 46170 | R29: FTR-021 | S29: Mock / seed data
A30: FTR-021 | B30: Contributor | C30: Task workroom & lifecycle | D30: Assigned → submit → review → approved flow | E30: P1 — Critical | F30: Phase 1 — MVP | G30: In Progress | H30: Complete | I30: In Progress | J30: =IF(G30="Completed",100,IF(G30="Deferred",0,IF(G30="Cancelled",0,IF(G30="Not Started",0,IF(G30="On Hold",IF(OR(H30="Complete",H30="N/A"),50,25),ROUND((IF(H30="Complete",100,IF(H30="In Progress",50,IF(H30="Blocked",25,0)))+IF(I30="Complete",100,IF(I30="In Progress",50,IF(I30="Blocked",25,IF(I30="N/A",100,0)))))/2,0)))))) | K30: =IF(G30="Completed","Green",IF(G30="Deferred","Grey",IF(G30="Cancelled","Grey",IF(G30="On Hold","Red",IF(J30>=80,"Green",IF(J30>=40,"Amber","Red")))))) | L30: Full Stack Developer | M30: Engineering Manager | N30: 46127 | O30: 46203 | Q30: 46170 | R30: FTR-090 | S30: localStorage today
A31: FTR-022 | B31: Contributor | C31: Submissions & revisions | D31: Deliverable submit and rework loop | E31: P1 — Critical | F31: Phase 1 — MVP | G31: In Progress | H31: Complete | I31: In Progress | J31: =IF(G31="Completed",100,IF(G31="Deferred",0,IF(G31="Cancelled",0,IF(G31="Not Started",0,IF(G31="On Hold",IF(OR(H31="Complete",H31="N/A"),50,25),ROUND((IF(H31="Complete",100,IF(H31="In Progress",50,IF(H31="Blocked",25,0)))+IF(I31="Complete",100,IF(I31="In Progress",50,IF(I31="Blocked",25,IF(I31="N/A",100,0)))))/2,0)))))) | K31: =IF(G31="Completed","Green",IF(G31="Deferred","Grey",IF(G31="Cancelled","Grey",IF(G31="On Hold","Red",IF(J31>=80,"Green",IF(J31>=40,"Amber","Red")))))) | L31: Full Stack Developer | M31: Engineering Manager | N31: 46127 | O31: 46203 | Q31: 46170 | R31: FTR-021
A32: FTR-023 | B32: Contributor | C32: Digital twin profile | D32: Skills, evidence, portfolio | E32: P2 — High | F32: Phase 1 — MVP | G32: In Progress | H32: Complete | I32: In Progress | J32: =IF(G32="Completed",100,IF(G32="Deferred",0,IF(G32="Cancelled",0,IF(G32="Not Started",0,IF(G32="On Hold",IF(OR(H32="Complete",H32="N/A"),50,25),ROUND((IF(H32="Complete",100,IF(H32="In Progress",50,IF(H32="Blocked",25,0)))+IF(I32="Complete",100,IF(I32="In Progress",50,IF(I32="Blocked",25,IF(I32="N/A",100,0)))))/2,0)))))) | K32: =IF(G32="Completed","Green",IF(G32="Deferred","Grey",IF(G32="Cancelled","Grey",IF(G32="On Hold","Red",IF(J32>=80,"Green",IF(J32>=40,"Amber","Red")))))) | L32: Full Stack Developer | M32: Engineering Manager | N32: 46113 | O32: 46188 | Q32: 46170 | R32: —
A33: FTR-024 | B33: Contributor | C33: Onboarding flow | D33: Multi-step contributor registration | E33: P1 — Critical | F33: Phase 1 — MVP | G33: In Progress | H33: Complete | I33: In Progress | J33: =IF(G33="Completed",100,IF(G33="Deferred",0,IF(G33="Cancelled",0,IF(G33="Not Started",0,IF(G33="On Hold",IF(OR(H33="Complete",H33="N/A"),50,25),ROUND((IF(H33="Complete",100,IF(H33="In Progress",50,IF(H33="Blocked",25,0)))+IF(I33="Complete",100,IF(I33="In Progress",50,IF(I33="Blocked",25,IF(I33="N/A",100,0)))))/2,0)))))) | K33: =IF(G33="Completed","Green",IF(G33="Deferred","Grey",IF(G33="Cancelled","Grey",IF(G33="On Hold","Red",IF(J33>=80,"Green",IF(J33>=40,"Amber","Red")))))) | L33: Full Stack Developer | M33: Engineering Manager | N33: 46113 | O33: 46174 | Q33: 46170 | R33: FTR-002
A34: FTR-025 | B34: Contributor | C34: Earnings & payouts view | D34: Contributor earnings dashboard | E34: P2 — High | F34: Phase 1 — Hardening | G34: In Progress | H34: Complete | I34: Not Started | J34: =IF(G34="Completed",100,IF(G34="Deferred",0,IF(G34="Cancelled",0,IF(G34="Not Started",0,IF(G34="On Hold",IF(OR(H34="Complete",H34="N/A"),50,25),ROUND((IF(H34="Complete",100,IF(H34="In Progress",50,IF(H34="Blocked",25,0)))+IF(I34="Complete",100,IF(I34="In Progress",50,IF(I34="Blocked",25,IF(I34="N/A",100,0)))))/2,0)))))) | K34: =IF(G34="Completed","Green",IF(G34="Deferred","Grey",IF(G34="Cancelled","Grey",IF(G34="On Hold","Red",IF(J34>=80,"Green",IF(J34>=40,"Amber","Red")))))) | L34: Frontend Lead | M34: Engineering Manager | N34: 46174 | O34: 46218 | Q34: 46170 | R34: FTR-014 | S34: Mock data
A35: FTR-026 | B35: Contributor | C35: Credentials wallet | D35: Issue, share, verify credentials | E35: P2 — High | F35: Phase 1 — MVP | G35: In Progress | H35: Complete | I35: In Progress | J35: =IF(G35="Completed",100,IF(G35="Deferred",0,IF(G35="Cancelled",0,IF(G35="Not Started",0,IF(G35="On Hold",IF(OR(H35="Complete",H35="N/A"),50,25),ROUND((IF(H35="Complete",100,IF(H35="In Progress",50,IF(H35="Blocked",25,0)))+IF(I35="Complete",100,IF(I35="In Progress",50,IF(I35="Blocked",25,IF(I35="N/A",100,0)))))/2,0)))))) | K35: =IF(G35="Completed","Green",IF(G35="Deferred","Grey",IF(G35="Cancelled","Grey",IF(G35="On Hold","Red",IF(J35>=80,"Green",IF(J35>=40,"Amber","Red")))))) | L35: Full Stack Developer | M35: Engineering Manager | N35: 46143 | O35: 46203 | Q35: 46170 | R35: — | S35: Public share page works
A36: FTR-027 | B36: Contributor | C36: Support & tickets | D36: FAQs, grievances, safety reports | E36: P3 — Medium | F36: Phase 1 — MVP | G36: In Progress | H36: Complete | I36: In Progress | J36: =IF(G36="Completed",100,IF(G36="Deferred",0,IF(G36="Cancelled",0,IF(G36="Not Started",0,IF(G36="On Hold",IF(OR(H36="Complete",H36="N/A"),50,25),ROUND((IF(H36="Complete",100,IF(H36="In Progress",50,IF(H36="Blocked",25,0)))+IF(I36="Complete",100,IF(I36="In Progress",50,IF(I36="Blocked",25,IF(I36="N/A",100,0)))))/2,0)))))) | K36: =IF(G36="Completed","Green",IF(G36="Deferred","Grey",IF(G36="Cancelled","Grey",IF(G36="On Hold","Red",IF(J36>=80,"Green",IF(J36>=40,"Amber","Red")))))) | L36: Full Stack Developer | M36: Engineering Manager | N36: 46143 | O36: 46204 | Q36: 46170 | R36: —
A37: FTR-028 | B37: Contributor | C37: Community & messages | D37: Community feed and messaging | E37: P3 — Medium | F37: Phase 2 | G37: Deferred | H37: Complete | I37: Not Started | J37: =IF(G37="Completed",100,IF(G37="Deferred",0,IF(G37="Cancelled",0,IF(G37="Not Started",0,IF(G37="On Hold",IF(OR(H37="Complete",H37="N/A"),50,25),ROUND((IF(H37="Complete",100,IF(H37="In Progress",50,IF(H37="Blocked",25,0)))+IF(I37="Complete",100,IF(I37="In Progress",50,IF(I37="Blocked",25,IF(I37="N/A",100,0)))))/2,0)))))) | K37: =IF(G37="Completed","Green",IF(G37="Deferred","Grey",IF(G37="Cancelled","Grey",IF(G37="On Hold","Red",IF(J37>=80,"Green",IF(J37>=40,"Amber","Red")))))) | L37: Frontend Lead | M37: Engineering Manager | N37: 46204 | O37: 46235 | Q37: 46170 | R37: — | S37: Visual-only mock
A38: FTR-029 | B38: Contributor | C38: Learning recommendations | D38: AI skill learning suggestions | E38: P3 — Medium | F38: Phase 2 | G38: Deferred | H38: Complete | I38: Not Started | J38: =IF(G38="Completed",100,IF(G38="Deferred",0,IF(G38="Cancelled",0,IF(G38="Not Started",0,IF(G38="On Hold",IF(OR(H38="Complete",H38="N/A"),50,25),ROUND((IF(H38="Complete",100,IF(H38="In Progress",50,IF(H38="Blocked",25,0)))+IF(I38="Complete",100,IF(I38="In Progress",50,IF(I38="Blocked",25,IF(I38="N/A",100,0)))))/2,0)))))) | K38: =IF(G38="Completed","Green",IF(G38="Deferred","Grey",IF(G38="Cancelled","Grey",IF(G38="On Hold","Red",IF(J38>=80,"Green",IF(J38>=40,"Amber","Red")))))) | L38: Frontend Lead | M38: Engineering Manager | N38: 46204 | O38: 46235 | Q38: 46170 | R38: FTR-097
A39: FTR-030 | B39: Contributor | C39: Account auth settings | D39: Password / OAuth / SSO mode selection | E39: P2 — High | F39: Phase 1 — MVP | G39: In Progress | H39: Complete | I39: In Progress | J39: =IF(G39="Completed",100,IF(G39="Deferred",0,IF(G39="Cancelled",0,IF(G39="Not Started",0,IF(G39="On Hold",IF(OR(H39="Complete",H39="N/A"),50,25),ROUND((IF(H39="Complete",100,IF(H39="In Progress",50,IF(H39="Blocked",25,0)))+IF(I39="Complete",100,IF(I39="In Progress",50,IF(I39="Blocked",25,IF(I39="N/A",100,0)))))/2,0)))))) | K39: =IF(G39="Completed","Green",IF(G39="Deferred","Grey",IF(G39="Cancelled","Grey",IF(G39="On Hold","Red",IF(J39>=80,"Green",IF(J39>=40,"Amber","Red")))))) | L39: Full Stack Developer | M39: Engineering Manager | N39: 46143 | O39: 46170 | Q39: 46170 | R39: FTR-003 | S39: Recently shipped
A40: FTR-040 | B40: Enterprise | C40: Dashboard | D40: Executive dashboard with KPIs and plan usage | E40: P1 — Critical | F40: Phase 1 — MVP | G40: In Progress | H40: Complete | I40: In Progress | J40: =IF(G40="Completed",100,IF(G40="Deferred",0,IF(G40="Cancelled",0,IF(G40="Not Started",0,IF(G40="On Hold",IF(OR(H40="Complete",H40="N/A"),50,25),ROUND((IF(H40="Complete",100,IF(H40="In Progress",50,IF(H40="Blocked",25,0)))+IF(I40="Complete",100,IF(I40="In Progress",50,IF(I40="Blocked",25,IF(I40="N/A",100,0)))))/2,0)))))) | K40: =IF(G40="Completed","Green",IF(G40="Deferred","Grey",IF(G40="Cancelled","Grey",IF(G40="On Hold","Red",IF(J40>=80,"Green",IF(J40>=40,"Amber","Red")))))) | L40: Frontend Lead | M40: Engineering Manager | N40: 46113 | O40: 46143 | Q40: 46170 | R40: FTR-016
A41: FTR-041 | B41: Enterprise | C41: SOW repository | D41: SOW list and detail views | E41: P1 — Critical | F41: Phase 1 — MVP | G41: In Progress | H41: Complete | I41: In Progress | J41: =IF(G41="Completed",100,IF(G41="Deferred",0,IF(G41="Cancelled",0,IF(G41="Not Started",0,IF(G41="On Hold",IF(OR(H41="Complete",H41="N/A"),50,25),ROUND((IF(H41="Complete",100,IF(H41="In Progress",50,IF(H41="Blocked",25,0)))+IF(I41="Complete",100,IF(I41="In Progress",50,IF(I41="Blocked",25,IF(I41="N/A",100,0)))))/2,0)))))) | K41: =IF(G41="Completed","Green",IF(G41="Deferred","Grey",IF(G41="Cancelled","Grey",IF(G41="On Hold","Red",IF(J41>=80,"Green",IF(J41>=40,"Amber","Red")))))) | L41: Full Stack Developer | M41: Engineering Manager | N41: 46113 | O41: 46188 | Q41: 46170 | R41: FTR-091 | S41: API + mocks hybrid
A42: FTR-042 | B42: Enterprise | C42: SOW intake (upload + AI) | D42: 5-stage intake wizard with AI extraction | E42: P1 — Critical | F42: Phase 1 — MVP | G42: In Progress | H42: Complete | I42: In Progress | J42: =IF(G42="Completed",100,IF(G42="Deferred",0,IF(G42="Cancelled",0,IF(G42="Not Started",0,IF(G42="On Hold",IF(OR(H42="Complete",H42="N/A"),50,25),ROUND((IF(H42="Complete",100,IF(H42="In Progress",50,IF(H42="Blocked",25,0)))+IF(I42="Complete",100,IF(I42="In Progress",50,IF(I42="Blocked",25,IF(I42="N/A",100,0)))))/2,0)))))) | K42: =IF(G42="Completed","Green",IF(G42="Deferred","Grey",IF(G42="Cancelled","Grey",IF(G42="On Hold","Red",IF(J42>=80,"Green",IF(J42>=40,"Amber","Red")))))) | L42: Full Stack Developer | M42: Engineering Manager | N42: 46127 | O42: 46203 | Q42: 46170 | R42: FTR-097 | S42: Commit local-state
A43: FTR-043 | B43: Enterprise | C43: SOW approval pipeline | D43: 5-stage commercial / legal sign-off | E43: P1 — Critical | F43: Phase 1 — MVP | G43: In Progress | H43: Complete | I43: In Progress | J43: =IF(G43="Completed",100,IF(G43="Deferred",0,IF(G43="Cancelled",0,IF(G43="Not Started",0,IF(G43="On Hold",IF(OR(H43="Complete",H43="N/A"),50,25),ROUND((IF(H43="Complete",100,IF(H43="In Progress",50,IF(H43="Blocked",25,0)))+IF(I43="Complete",100,IF(I43="In Progress",50,IF(I43="Blocked",25,IF(I43="N/A",100,0)))))/2,0)))))) | K43: =IF(G43="Completed","Green",IF(G43="Deferred","Grey",IF(G43="Cancelled","Grey",IF(G43="On Hold","Red",IF(J43>=80,"Green",IF(J43>=40,"Amber","Red")))))) | L43: Full Stack Developer | M43: Engineering Manager | N43: 46127 | O43: 46203 | Q43: 46170 | R43: FTR-041
A44: FTR-044 | B44: Enterprise | C44: Decomposition workspace | D44: Break SOW into workstreams and tasks | E44: P1 — Critical | F44: Phase 1 — MVP | G44: In Progress | H44: Complete | I44: Not Started | J44: =IF(G44="Completed",100,IF(G44="Deferred",0,IF(G44="Cancelled",0,IF(G44="Not Started",0,IF(G44="On Hold",IF(OR(H44="Complete",H44="N/A"),50,25),ROUND((IF(H44="Complete",100,IF(H44="In Progress",50,IF(H44="Blocked",25,0)))+IF(I44="Complete",100,IF(I44="In Progress",50,IF(I44="Blocked",25,IF(I44="N/A",100,0)))))/2,0)))))) | K44: =IF(G44="Completed","Green",IF(G44="Deferred","Grey",IF(G44="Cancelled","Grey",IF(G44="On Hold","Red",IF(J44>=80,"Green",IF(J44>=40,"Amber","Red")))))) | L44: Full Stack Developer | M44: Engineering Manager | N44: 46143 | O44: 46204 | Q44: 46170 | R44: FTR-091 | S44: Mock plans
A45: FTR-045 | B45: Enterprise | C45: Team matching & formation | D45: Suggest and assign contributors | E45: P2 — High | F45: Phase 1 — MVP | G45: In Progress | H45: Complete | I45: Not Started | J45: =IF(G45="Completed",100,IF(G45="Deferred",0,IF(G45="Cancelled",0,IF(G45="Not Started",0,IF(G45="On Hold",IF(OR(H45="Complete",H45="N/A"),50,25),ROUND((IF(H45="Complete",100,IF(H45="In Progress",50,IF(H45="Blocked",25,0)))+IF(I45="Complete",100,IF(I45="In Progress",50,IF(I45="Blocked",25,IF(I45="N/A",100,0)))))/2,0)))))) | K45: =IF(G45="Completed","Green",IF(G45="Deferred","Grey",IF(G45="Cancelled","Grey",IF(G45="On Hold","Red",IF(J45>=80,"Green",IF(J45>=40,"Amber","Red")))))) | L45: Frontend Lead | M45: Engineering Manager | N45: 46157 | O45: 46218 | Q45: 46170 | R45: FTR-044
A46: FTR-046 | B46: Enterprise | C46: Projects portfolio | D46: Active and completed project tiles | E46: P1 — Critical | F46: Phase 1 — MVP | G46: In Progress | H46: Complete | I46: Not Started | J46: =IF(G46="Completed",100,IF(G46="Deferred",0,IF(G46="Cancelled",0,IF(G46="Not Started",0,IF(G46="On Hold",IF(OR(H46="Complete",H46="N/A"),50,25),ROUND((IF(H46="Complete",100,IF(H46="In Progress",50,IF(H46="Blocked",25,0)))+IF(I46="Complete",100,IF(I46="In Progress",50,IF(I46="Blocked",25,IF(I46="N/A",100,0)))))/2,0)))))) | K46: =IF(G46="Completed","Green",IF(G46="Deferred","Grey",IF(G46="Cancelled","Grey",IF(G46="On Hold","Red",IF(J46>=80,"Green",IF(J46>=40,"Amber","Red")))))) | L46: Full Stack Developer | M46: Engineering Manager | N46: 46143 | O46: 46204 | Q46: 46170 | R46: FTR-091
A47: FTR-047 | B47: Enterprise | C47: Delivery tracking | D47: Milestones, exceptions, lifecycle view | E47: P1 — Critical | F47: Phase 1 — MVP | G47: In Progress | H47: Complete | I47: Not Started | J47: =IF(G47="Completed",100,IF(G47="Deferred",0,IF(G47="Cancelled",0,IF(G47="Not Started",0,IF(G47="On Hold",IF(OR(H47="Complete",H47="N/A"),50,25),ROUND((IF(H47="Complete",100,IF(H47="In Progress",50,IF(H47="Blocked",25,0)))+IF(I47="Complete",100,IF(I47="In Progress",50,IF(I47="Blocked",25,IF(I47="N/A",100,0)))))/2,0)))))) | K47: =IF(G47="Completed","Green",IF(G47="Deferred","Grey",IF(G47="Cancelled","Grey",IF(G47="On Hold","Red",IF(J47>=80,"Green",IF(J47>=40,"Amber","Red")))))) | L47: Full Stack Developer | M47: Engineering Manager | N47: 46143 | O47: 46204 | Q47: 46170 | R47: FTR-021
A48: FTR-048 | B48: Enterprise | C48: Review & acceptance queue | D48: Accept / rework deliverables | E48: P1 — Critical | F48: Phase 1 — MVP | G48: In Progress | H48: Complete | I48: In Progress | J48: =IF(G48="Completed",100,IF(G48="Deferred",0,IF(G48="Cancelled",0,IF(G48="Not Started",0,IF(G48="On Hold",IF(OR(H48="Complete",H48="N/A"),50,25),ROUND((IF(H48="Complete",100,IF(H48="In Progress",50,IF(H48="Blocked",25,0)))+IF(I48="Complete",100,IF(I48="In Progress",50,IF(I48="Blocked",25,IF(I48="N/A",100,0)))))/2,0)))))) | K48: =IF(G48="Completed","Green",IF(G48="Deferred","Grey",IF(G48="Cancelled","Grey",IF(G48="On Hold","Red",IF(J48>=80,"Green",IF(J48>=40,"Amber","Red")))))) | L48: Full Stack Developer | M48: Engineering Manager | N48: 46127 | O48: 46174 | Q48: 46170 | R48: FTR-015 | S48: Postgres audit log
...

Sheet Dashboard
A1: Program Dashboard
A2: As of 28 May 2026 · sourced from Feature Register
A4: Total features | C4: Completed | E4: In progress | G4: Not started
A5: =COUNTA('Feature Register'!A12:A87) | C5: =COUNTIF('Feature Register'!G12:G87,"Completed") | E5: =COUNTIF('Feature Register'!G12:G87,"In Progress") | G5: =COUNTIF('Feature Register'!G12:G87,"Not Started")
A7: P1 critical (open) | C7: Avg % complete | E7: Red / Amber (RAG) | G7: Deferred (Phase 2)
A8: =COUNTIFS('Feature Register'!E12:E87,"P1*",'Feature Register'!G12:G87,"<>Completed",'Feature Register'!G12:G87,"<>Deferred",'Feature Register'!G12:G87,"<>Cancelled") | C8: =IFERROR(AVERAGE('Feature Register'!J12:J87),0) | E8: =COUNTIF('Feature Register'!K12:K87,"Red")&" / "&COUNTIF('Feature Register'!K12:K87,"Amber") | G8: =COUNTIF('Feature Register'!G12:G87,"Deferred")
A12: By module
A13: Module | B13: Total | C13: Completed | D13: In Progress | E13: Not Started | F13: Avg %
A14: Platform | B14: =COUNTIF('Feature Register'!B12:B87,"Platform") | C14: =COUNTIFS('Feature Register'!B12:B87,"Platform",'Feature Register'!G12:G87,"Completed") | D14: =COUNTIFS('Feature Register'!B12:B87,"Platform",'Feature Register'!G12:G87,"In Progress") | E14: =COUNTIFS('Feature Register'!B12:B87,"Platform",'Feature Register'!G12:G87,"Not Started") | F14: =IFERROR(AVERAGEIF('Feature Register'!B12:B87,"Platform",'Feature Register'!J12:J87),0)
A15: Contributor | B15: =COUNTIF('Feature Register'!B12:B87,"Contributor") | C15: =COUNTIFS('Feature Register'!B12:B87,"Contributor",'Feature Register'!G12:G87,"Completed") | D15: =COUNTIFS('Feature Register'!B12:B87,"Contributor",'Feature Register'!G12:G87,"In Progress") | E15: =COUNTIFS('Feature Register'!B12:B87,"Contributor",'Feature Register'!G12:G87,"Not Started") | F15: =IFERROR(AVERAGEIF('Feature Register'!B12:B87,"Contributor",'Feature Register'!J12:J87),0)
A16: Enterprise | B16: =COUNTIF('Feature Register'!B12:B87,"Enterprise") | C16: =COUNTIFS('Feature Register'!B12:B87,"Enterprise",'Feature Register'!G12:G87,"Completed") | D16: =COUNTIFS('Feature Register'!B12:B87,"Enterprise",'Feature Register'!G12:G87,"In Progress") | E16: =COUNTIFS('Feature Register'!B12:B87,"Enterprise",'Feature Register'!G12:G87,"Not Started") | F16: =IFERROR(AVERAGEIF('Feature Register'!B12:B87,"Enterprise",'Feature Register'!J12:J87),0)
A17: Mentor | B17: =COUNTIF('Feature Register'!B12:B87,"Mentor") | C17: =COUNTIFS('Feature Register'!B12:B87,"Mentor",'Feature Register'!G12:G87,"Completed") | D17: =COUNTIFS('Feature Register'!B12:B87,"Mentor",'Feature Register'!G12:G87,"In Progress") | E17: =COUNTIFS('Feature Register'!B12:B87,"Mentor",'Feature Register'!G12:G87,"Not Started") | F17: =IFERROR(AVERAGEIF('Feature Register'!B12:B87,"Mentor",'Feature Register'!J12:J87),0)
A18: Admin | B18: =COUNTIF('Feature Register'!B12:B87,"Admin") | C18: =COUNTIFS('Feature Register'!B12:B87,"Admin",'Feature Register'!G12:G87,"Completed") | D18: =COUNTIFS('Feature Register'!B12:B87,"Admin",'Feature Register'!G12:G87,"In Progress") | E18: =COUNTIFS('Feature Register'!B12:B87,"Admin",'Feature Register'!G12:G87,"Not Started") | F18: =IFERROR(AVERAGEIF('Feature Register'!B12:B87,"Admin",'Feature Register'!J12:J87),0)
A19: Backend | B19: =COUNTIF('Feature Register'!B12:B87,"Backend") | C19: =COUNTIFS('Feature Register'!B12:B87,"Backend",'Feature Register'!G12:G87,"Completed") | D19: =COUNTIFS('Feature Register'!B12:B87,"Backend",'Feature Register'!G12:G87,"In Progress") | E19: =COUNTIFS('Feature Register'!B12:B87,"Backend",'Feature Register'!G12:G87,"Not Started") | F19: =IFERROR(AVERAGEIF('Feature Register'!B12:B87,"Backend",'Feature Register'!J12:J87),0)

Sheet Resource Plan
A1: Resource Plan — by assignee
A2: Standard workload view · who owns how many open items
A4: Assigned To | B4: Total assigned | C4: Completed | D4: In progress | E4: Not started | F4: Open P1 items
A5: Product Manager | B5: =COUNTIF('Feature Register'!L12:L87,A5) | C5: =COUNTIFS('Feature Register'!L12:L87,A5,'Feature Register'!G12:G87,"Completed") | D5: =COUNTIFS('Feature Register'!L12:L87,A5,'Feature Register'!G12:G87,"In Progress") | E5: =COUNTIFS('Feature Register'!L12:L87,A5,'Feature Register'!G12:G87,"Not Started") | F5: =COUNTIFS('Feature Register'!L12:L87,A5,'Feature Register'!E12:E87,"P1*",'Feature Register'!G12:G87,"<>Completed")
A6: Engineering Manager | B6: =COUNTIF('Feature Register'!L12:L87,A6) | C6: =COUNTIFS('Feature Register'!L12:L87,A6,'Feature Register'!G12:G87,"Completed") | D6: =COUNTIFS('Feature Register'!L12:L87,A6,'Feature Register'!G12:G87,"In Progress") | E6: =COUNTIFS('Feature Register'!L12:L87,A6,'Feature Register'!G12:G87,"Not Started") | F6: =COUNTIFS('Feature Register'!L12:L87,A6,'Feature Register'!E12:E87,"P1*",'Feature Register'!G12:G87,"<>Completed")
A7: Frontend Lead | B7: =COUNTIF('Feature Register'!L12:L87,A7) | C7: =COUNTIFS('Feature Register'!L12:L87,A7,'Feature Register'!G12:G87,"Completed") | D7: =COUNTIFS('Feature Register'!L12:L87,A7,'Feature Register'!G12:G87,"In Progress") | E7: =COUNTIFS('Feature Register'!L12:L87,A7,'Feature Register'!G12:G87,"Not Started") | F7: =COUNTIFS('Feature Register'!L12:L87,A7,'Feature Register'!E12:E87,"P1*",'Feature Register'!G12:G87,"<>Completed")
A8: Backend Lead | B8: =COUNTIF('Feature Register'!L12:L87,A8) | C8: =COUNTIFS('Feature Register'!L12:L87,A8,'Feature Register'!G12:G87,"Completed") | D8: =COUNTIFS('Feature Register'!L12:L87,A8,'Feature Register'!G12:G87,"In Progress") | E8: =COUNTIFS('Feature Register'!L12:L87,A8,'Feature Register'!G12:G87,"Not Started") | F8: =COUNTIFS('Feature Register'!L12:L87,A8,'Feature Register'!E12:E87,"P1*",'Feature Register'!G12:G87,"<>Completed")
A9: Full Stack Developer | B9: =COUNTIF('Feature Register'!L12:L87,A9) | C9: =COUNTIFS('Feature Register'!L12:L87,A9,'Feature Register'!G12:G87,"Completed") | D9: =COUNTIFS('Feature Register'!L12:L87,A9,'Feature Register'!G12:G87,"In Progress") | E9: =COUNTIFS('Feature Register'!L12:L87,A9,'Feature Register'!G12:G87,"Not Started") | F9: =COUNTIFS('Feature Register'!L12:L87,A9,'Feature Register'!E12:E87,"P1*",'Feature Register'!G12:G87,"<>Completed")
A10: QA Lead | B10: =COUNTIF('Feature Register'!L12:L87,A10) | C10: =COUNTIFS('Feature Register'!L12:L87,A10,'Feature Register'!G12:G87,"Completed") | D10: =COUNTIFS('Feature Register'!L12:L87,A10,'Feature Register'!G12:G87,"In Progress") | E10: =COUNTIFS('Feature Register'!L12:L87,A10,'Feature Register'!G12:G87,"Not Started") | F10: =COUNTIFS('Feature Register'!L12:L87,A10,'Feature Register'!E12:E87,"P1*",'Feature Register'!G12:G87,"<>Completed")
A11: DevOps / SRE | B11: =COUNTIF('Feature Register'!L12:L87,A11) | C11: =COUNTIFS('Feature Register'!L12:L87,A11,'Feature Register'!G12:G87,"Completed") | D11: =COUNTIFS('Feature Register'!L12:L87,A11,'Feature Register'!G12:G87,"In Progress") | E11: =COUNTIFS('Feature Register'!L12:L87,A11,'Feature Register'!G12:G87,"Not Started") | F11: =COUNTIFS('Feature Register'!L12:L87,A11,'Feature Register'!E12:E87,"P1*",'Feature Register'!G12:G87,"<>Completed")
A12: Security Lead | B12: =COUNTIF('Feature Register'!L12:L87,A12) | C12: =COUNTIFS('Feature Register'!L12:L87,A12,'Feature Register'!G12:G87,"Completed") | D12: =COUNTIFS('Feature Register'!L12:L87,A12,'Feature Register'!G12:G87,"In Progress") | E12: =COUNTIFS('Feature Register'!L12:L87,A12,'Feature Register'!G12:G87,"Not Started") | F12: =COUNTIFS('Feature Register'!L12:L87,A12,'Feature Register'!E12:E87,"P1*",'Feature Register'!G12:G87,"<>Completed")
A13: UI/UX Designer | B13: =COUNTIF('Feature Register'!L12:L87,A13) | C13: =COUNTIFS('Feature Register'!L12:L87,A13,'Feature Register'!G12:G87,"Completed") | D13: =COUNTIFS('Feature Register'!L12:L87,A13,'Feature Register'!G12:G87,"In Progress") | E13: =COUNTIFS('Feature Register'!L12:L87,A13,'Feature Register'!G12:G87,"Not Started") | F13: =COUNTIFS('Feature Register'!L12:L87,A13,'Feature Register'!E12:E87,"P1*",'Feature Register'!G12:G87,"<>Completed")
A14: Integrations Lead | B14: =COUNTIF('Feature Register'!L12:L87,A14) | C14: =COUNTIFS('Feature Register'!L12:L87,A14,'Feature Register'!G12:G87,"Completed") | D14: =COUNTIFS('Feature Register'!L12:L87,A14,'Feature Register'!G12:G87,"In Progress") | E14: =COUNTIFS('Feature Register'!L12:L87,A14,'Feature Register'!G12:G87,"Not Started") | F14: =COUNTIFS('Feature Register'!L12:L87,A14,'Feature Register'!E12:E87,"P1*",'Feature Register'!G12:G87,"<>Completed")
A15: AI / ML Engineer | B15: =COUNTIF('Feature Register'!L12:L87,A15) | C15: =COUNTIFS('Feature Register'!L12:L87,A15,'Feature Register'!G12:G87,"Completed") | D15: =COUNTIFS('Feature Register'!L12:L87,A15,'Feature Register'!G12:G87,"In Progress") | E15: =COUNTIFS('Feature Register'!L12:L87,A15,'Feature Register'!G12:G87,"Not Started") | F15: =COUNTIFS('Feature Register'!L12:L87,A15,'Feature Register'!E12:E87,"P1*",'Feature Register'!G12:G87,"<>Completed")

Sheet Definitions
A1: Column & status definitions
A3: Field | B3: Definition
A4: Feature ID | B4: Unique reference (FTR-xxx). Used in dependencies.
A5: Module | B5: Product area: Platform, Contributor, Enterprise, Mentor, Admin, Backend.
A6: Overall Status | B6: Not Started → In Progress → Completed. Also: On Hold, Cancelled, Deferred.
A7: Frontend / Backend Status | B7: Delivery layer status. Use N/A when not applicable (e.g. backend-only).
A8: % Complete | B8: Auto-calculated from overall + FE/BE status.
A9: RAG | B9: Auto: Green (on track), Amber (attention), Red (blocked/overdue risk), Grey (deferred).
A10: Assigned To | B10: Person doing the work (developer / lead).
A11: Accountable (EM) | B11: Manager accountable for delivery sign-off.
A12: Planned Start / End | B12: Baseline schedule dates.
A13: Actual End | B13: Fill when Overall Status = Completed.
A14: Dependency ID | B14: Feature ID that must complete first.
A15: Remarks | B15: Blockers, decisions, links to PRD / ticket.
